<?xml version='1.0' encoding='utf-8'?>
<mujoco model="integrated_arm_left">
  <!--robola compile-->
  <compiler angle="radian" />

  <asset>
    <texture type="2d" colorspace="auto" name="Texture" builtin="gradient" rgb1="0.2 0.3 0.4" rgb2="0.9 0.9 0.9" width="512" height="512" />
    <texture type="2d" colorspace="auto" name="gripper_tex" builtin="flat" rgb1="0.55 0.55 0.55" width="256" height="256" />
    <texture type="2d" colorspace="auto" name="elp_tex" builtin="flat" rgb1="0.15 0.15 0.15" width="256" height="256" />
    <material name="Material" texuniform="true" metallic="0" roughness="1" rgba="0.5 0.5 0.5 1" />
    <material name="gripper_mat" texture="gripper_tex" rgba="0.75 0.75 0.75 1" />
    <material name="elp_mat" texture="elp_tex" rgba="0.2 0.2 0.2 1" />
    <mesh name="left_base_link" file="../../assets/meshes/robots/fairino5_v6/base_link.STL" />
    <mesh name="left_shoulder_link" file="../../assets/meshes/robots/fairino5_v6/shoulder_link.STL" />
    <mesh name="left_upperarm_link" file="../../assets/meshes/robots/fairino5_v6/upperarm_link.STL" />
    <mesh name="left_forearm_link" file="../../assets/meshes/robots/fairino5_v6/forearm_link.STL" />
    <mesh name="left_wrist1_link" file="../../assets/meshes/robots/fairino5_v6/wrist1_link.STL" />
    <mesh name="left_wrist2_link" file="../../assets/meshes/robots/fairino5_v6/wrist2_link.STL" />
    <mesh name="left_wrist3_link" file="../../assets/meshes/robots/fairino5_v6/wrist3_link.STL" />
    <mesh name="iai_upper_body" file="../../assets/meshes/gripper/iai/upper_body.stl" scale="0.001 0.001 0.001" />
    <mesh name="iai_lower_body" file="../../assets/meshes/gripper/iai/lower_body.stl" scale="0.001 0.001 0.001" />
    <mesh name="iai_left_pinch" file="../../assets/meshes/gripper/iai/left_pinch.stl" scale="0.001 0.001 0.001" />
    <mesh name="iai_right_pinch" file="../../assets/meshes/gripper/iai/right_pinch.stl" scale="0.001 0.001 0.001" />
    <mesh name="iai_cable" file="../../assets/meshes/gripper/iai/cable.stl" scale="0.001 0.001 0.001" />
    <mesh name="iai_side" file="../../assets/meshes/gripper/iai/gripper_side.stl" scale="0.001 0.001 0.001" />
    <mesh name="iai_claw" file="../../assets/meshes/gripper/iai/claw.stl" scale="0.001 0.001 0.001" />
    <mesh name="iai_gripper_cover" file="../../assets/meshes/gripper/iai/gripper_cover.stl" scale="0.001 0.001 0.001" />
    <mesh name="iai_connect_part" file="../../assets/meshes/gripper/iai/connect_part.stl" scale="0.001 0.001 0.001" />
    <mesh name="elp_cam_mesh" file="../../assets/meshes/camera/elp_cam.stl" scale="0.001 0.001 0.001" />
  </asset>

  <worldbody>
    <body name="left/fairino5_v6_root_frame" pos="-0.0360868 0.910242 0.8" quat="0.707107 0 0 -0.707107">
      <body name="left/fairino5_v6_body">
        <body name="left/base_link">
          <inertial pos="-0.00031896 -0.00029673 0.042463" quat="-0.270348 -0.648174 0.282295 -0.653523" mass="1.6185" diaginertia="0.00452139 0.00309793 0.00306769" />
          <geom name="left/geom_0_" type="mesh" contype="0" conaffinity="0" group="2" density="0" mesh="left_base_link" />
          <body name="left/shoulder_link">
            <inertial pos="5.0029e-07 -0.0040922 0.14629" quat="0.999588 0.0287044 7.54149e-06 -1.58789e-05" mass="4.3771" diaginertia="0.010731 0.0104154 0.00817191" />
            <joint name="left/j1" pos="0 0 0" axis="0 0 1" range="-3.0543 3.0543" actuatorgravcomp="true" armature="1" damping="10" />
            <geom name="left/geom_1_" type="mesh" contype="0" conaffinity="0" group="2" density="0" mesh="left_shoulder_link" />
            <body name="left/upperarm_link" pos="0 0 0.152" quat="0.707105 0.707108 0 0">
              <inertial pos="-0.2125 -5.7643e-09 0.1346" quat="0.5 0.5 0.5 0.5" mass="14.458" diaginertia="0.4559 0.44974 0.028392" />
              <joint name="left/j2" pos="0 0 0" axis="0 0 1" ref="-0.072" range="-4.6251 1.4835" actuatorgravcomp="true" armature="0.5" damping="10" frictionloss="0.5" />
              <geom name="left/geom_2_" type="mesh" contype="0" conaffinity="0" group="2" density="0" mesh="left_upperarm_link" />
              <body name="left/forearm_link" pos="-0.425 0 0">
                <inertial pos="-0.18793 -8.4503e-07 0.0066357" quat="0.510607 0.489172 0.489196 0.510568" mass="7.6737" diaginertia="0.16971 0.168834 0.00821541" />
                <joint name="left/j3" pos="0 0 0" axis="0 0 1" range="-2.8274 2.8274" actuatorgravcomp="true" armature="0.3" damping="8" frictionloss="0.3" />
                <geom name="left/geom_3_" type="mesh" contype="0" conaffinity="0" group="2" density="0" mesh="left_forearm_link" />
                <body name="left/wrist1_link" pos="-0.39501 0 0">
                  <inertial pos="4.98e-07 -0.003754 0.097155" quat="0.736149 0.676819 -6.33095e-05 7.15237e-05" mass="1.6266" diaginertia="0.00216 0.00199337 0.00154233" />
                  <joint name="left/j4" pos="0 0 0" axis="0 0 1" range="-4.6251 1.4835" actuatorgravcomp="true" armature="0.1" damping="3" frictionloss="0.1" />
                  <geom name="left/geom_4_" type="mesh" contype="0" conaffinity="0" group="2" density="0" mesh="left_wrist1_link" />
                  <body name="left/wrist2_link" pos="0 0 0.1021" quat="0.707105 0.707108 0 0">
                    <inertial pos="-4.5588e-07 0.0038617 0.098257" quat="0.68712 0.726544 0.000128667 -0.000114125" mass="1.5812" diaginertia="0.0020612 0.00195889 0.00144611" />
                    <joint name="left/j5" pos="0 0 0" axis="0 0 1" range="-3.0543 3.0543" actuatorgravcomp="true" armature="0.1" damping="3" frictionloss="0.1" />
                    <geom name="left/geom_5_" type="mesh" group="2" density="0" mesh="left_wrist2_link" />
                    <body name="left/wrist3_link" pos="0 0 0.102" quat="0 0 0.707105 0.707108">
                      <inertial pos="7.7496e-05 1.7751e-05 0.076122" quat="7.93213e-05 0.706804 0.00108234 0.707408" mass="0.52542" diaginertia="0.00041605 0.00027839 0.00027721" />
                      <joint name="left/j6" pos="0 0 0" axis="0 0 1" range="-3.0543 3.0543" actuatorgravcomp="true" armature="0.05" damping="2" frictionloss="0.1" />
                      <geom name="left/geom_6_" type="mesh" group="2" mesh="left_wrist3_link" />
                      <site name="left/link_tcp" pos="0 0 0.102" size="0.001" group="4" rgba="1 0 0 1" />
                      <site name="left/attachment_site" pos="0 0 0.102" size="0.001" group="5" rgba="1 0 0 1" />
                      <body name="gripper/base" pos="0 -8.18396e-08 0.202095" quat="0.707107 0.707107 0 0">
                        <inertial pos="0 0 0.0002" mass="0.6" diaginertia="0.001 0.001 0.001" />
                        <geom name="upper_body" pos="0.000545159 0 0.0021" quat="0 1 0 0" type="mesh" contype="0" conaffinity="0" density="5" material="gripper_mat" mesh="iai_upper_body" />
                        <geom name="lower_body" pos="0 -0.0410198 -0.0147173" quat="0 1 0 0" type="mesh" group="2" material="gripper_mat" mesh="iai_lower_body" />
                        <geom name="cable" pos="0.00559816 -0.0699537 -0.0479794" quat="0.707107 0 0.707107 0" type="mesh" group="2" material="gripper_mat" mesh="iai_cable" />
                        <geom name="right_side" pos="0 -0.0802952 0" quat="1 0 0 0" type="mesh" material="gripper_mat" mesh="iai_side" />
                        <geom name="left_side" pos="-0.0765432 -0.0806754 0" quat="1 0 0 0" type="mesh" material="gripper_mat" mesh="iai_side" />
                        <geom name="cover" pos="0 0.18463 -0.0489517" quat="0 0 0 1" type="mesh" material="gripper_mat" mesh="iai_gripper_cover" />
                        <geom name="connector" pos="0 0.000735604 -0.0340329" quat="0 0 0 1" type="mesh" material="gripper_mat" mesh="iai_connect_part" />
                        <body name="right_pinch">
                          <joint name="right_pinch" pos="0.02 0 0" axis="-1 0 0" type="slide" limited="true" range="-0.015 0.015" actuatorfrclimited="false" actuatorgravcomp="true" armature="0.001" damping="0.2" />
                          <geom name="right_pinch" pos="0.0243746 0.00245222 0.00147149" quat="0 0 0 1" type="mesh" friction="0" density="1" material="gripper_mat" mesh="iai_right_pinch" />
                          <geom name="right_claw" pos="0.00833277 0.0089508 -0.00681747" quat="0 1 0 0" type="mesh" mass="1e-09" material="gripper_mat" mesh="iai_claw" />
                        </body>
                        <body name="left_pinch">
                          <joint name="left_pinch" pos="-0.02 0 0" axis="1 0 0" type="slide" limited="true" range="-0.015 0.015" actuatorfrclimited="false" actuatorgravcomp="true" armature="0.001" damping="0.2" />
                          <geom name="left_pinch" pos="-0.0232227 0.00214457 0.00154222" quat="0 0 0 1" type="mesh" friction="0" density="1" material="gripper_mat" mesh="iai_left_pinch" />
                          <geom name="left_claw" pos="-0.00733679 0.00840771 0.009739" quat="0 0 0 1" type="mesh" mass="1e-09" material="gripper_mat" mesh="iai_claw" />
                        </body>
                      </body>
                      <body name="elp/base" pos="0 0 0.15" quat="0 0 0 1">
                        <inertial pos="0 0 0" mass="0.08" diaginertia="5e-05 5e-05 5e-05" />
                        <geom name="elp/body" pos="0.0288847 0.104262 -0.0295712" quat="0.707107 0 0 0.707107" type="mesh" contype="0" conaffinity="0" group="2" material="elp_mat" mesh="elp_cam_mesh" />
                        <site name="elp/mount_site" pos="-0.0568629 0.0413539 0.0115667" quat="0.707107 0 0.707107 0" size="2e-06" group="5" rgba="0 1 0 1" />
                        <site name="elp/optical_site" pos="-0.0291295 0.0286639 0.0417027" size="2e-06" group="5" rgba="1 0 0 1" />
                        <camera name="elp/rgb" pos="-0.0289568 0.0285627 0.0376585" quat="0 0.707107 -0.707107 0" fovy="70" />
                      </body>
                    </body>
                  </body>
                </body>
              </body>
            </body>
          </body>
        </body>
      </body>
    </body>
  </worldbody>

  <contact>
    <pair geom1="right_side" geom2="right_pinch" name="gripper_pair_1" />
    <pair geom1="left_side" geom2="left_pinch" name="gripper_pair_2" />
    <exclude name="exclude_1" body1="left/base_link" body2="left/shoulder_link" />
    <exclude name="gripper_exclude_1" body1="gripper/base" body2="right_pinch" />
    <exclude name="gripper_exclude_2" body1="gripper/base" body2="left_pinch" />
  </contact>

  <equality>
    <joint name="new_equality" joint1="right_pinch" joint2="left_pinch" polycoef="0 1 0 0 0" />
  </equality>

  <actuator>
    <general name="left/act1" joint="left/j1" ctrlrange="-3.0543 3.0543" dynprm="0 0 0 0 0 0 0 0 0 0" biastype="affine" gainprm="900" biasprm="0 -900 -180" />
    <general name="left/act2" joint="left/j2" ctrlrange="-4.6251 1.4835" dynprm="0 0 0 0 0 0 0 0 0 0" biastype="affine" gainprm="1200" biasprm="0 -1200 -240" />
    <general name="left/act3" joint="left/j3" ctrlrange="-2.8274 2.8274" dynprm="0 0 0 0 0 0 0 0 0 0" biastype="affine" gainprm="1300" biasprm="0 -1300 -260" />
    <general name="left/act4" joint="left/j4" ctrlrange="-4.6251 1.4835" dynprm="0 0 0 0 0 0 0 0 0 0" biastype="affine" gainprm="160" biasprm="0 -160 -35" />
    <general name="left/act5" joint="left/j5" ctrlrange="-3.0543 3.0543" dynprm="0 0 0 0 0 0 0 0 0 0" biastype="affine" gainprm="140" biasprm="0 -140 -30" />
    <general name="left/act6" joint="left/j6" ctrlrange="-3.0543 3.0543" dynprm="0 0 0 0 0 0 0 0 0 0" biastype="affine" gainprm="140" biasprm="0 -140 -30" />
    <general name="left/gripper_actuator" joint="right_pinch" ctrllimited="true" ctrlrange="-0.015 0.015" dynprm="0 0 0 0 0 0 0 0 0 0" biastype="affine" gainprm="5" biasprm="0 -5" />
  </actuator>
</mujoco>