<?xml version='1.0' encoding='utf-8'?>
<mujoco model="iai_gripper">
  <!--robola compile-->
  <compiler angle="radian" meshdir="../../../assets/meshes/" />

  <asset>
    <texture type="2d" colorspace="auto" name="gripper_tex" builtin="flat" rgb1="0.55 0.55 0.55" width="256" height="256" />
    <material name="gripper_mat" texture="gripper_tex" rgba="0.75 0.75 0.75 1" />
    <mesh name="iai_upper_body" content_type="model/stl" file="gripper/iai/upper_body.stl" />
    <mesh name="iai_lower_body" content_type="model/stl" file="gripper/iai/lower_body.stl" />
    <mesh name="iai_left_pinch" content_type="model/stl" file="gripper/iai/left_pinch.stl" />
    <mesh name="iai_right_pinch" content_type="model/stl" file="gripper/iai/right_pinch.stl" />
    <mesh name="iai_cable" content_type="model/stl" file="gripper/iai/cable.stl" />
    <mesh name="iai_side" content_type="model/stl" file="gripper/iai/gripper_side.stl" />
    <mesh name="iai_claw" content_type="model/stl" file="gripper/iai/claw.stl" />
    <mesh name="iai_gripper_cover" content_type="model/stl" file="gripper/iai/gripper_cover.stl" />
    <mesh name="iai_connect_part" content_type="model/stl" file="gripper/iai/connect_part.stl" />
  </asset>

  <worldbody>
    <body name="gripper/base">
      <inertial pos="0 0 0.2" mass="0.6" diaginertia="0.001 0.001 0.001" />
      <geom name="upper_body" pos="0.545159 0 2.1" quat="0 1 0 0" type="mesh" contype="0" conaffinity="0" density="5" material="gripper_mat" mesh="iai_upper_body" />
      <geom name="lower_body" pos="0 -41.0198 -14.7173" quat="0 1 0 0" type="mesh" group="2" material="gripper_mat" mesh="iai_lower_body" />
      <geom name="cable" pos="5.59816 -69.9537 -47.9794" quat="0.707107 0 0.707107 0" type="mesh" group="2" material="gripper_mat" mesh="iai_cable" />
      <geom name="right_side" pos="0 -80.2952 0" quat="1 0 0 0" type="mesh" material="gripper_mat" mesh="iai_side" />
      <geom name="left_side" pos="-76.5432 -80.6754 0" quat="1 0 0 0" type="mesh" material="gripper_mat" mesh="iai_side" />
      <geom name="cover" pos="0 184.63 -48.9517" quat="0 0 0 1" type="mesh" material="gripper_mat" mesh="iai_gripper_cover" />
      <geom name="connector" pos="0 0.735604 -34.0329" quat="0 0 0 1" type="mesh" material="gripper_mat" mesh="iai_connect_part" />
      <body name="right_pinch">
        <joint name="right_pinch" pos="20 0 0" axis="-1 0 0" type="slide" limited="true" range="0 15" actuatorfrclimited="false" actuatorgravcomp="true" />
        <geom name="right_pinch" pos="24.3746 2.45222 1.47149" quat="0 0 0 1" type="mesh" friction="0" density="1" material="gripper_mat" mesh="iai_right_pinch" />
        <geom name="right_claw" pos="8.33277 8.9508 -6.81747" quat="0 1 0 0" type="mesh" mass="1e-09" material="gripper_mat" mesh="iai_claw" />
      </body>
      <body name="left_pinch">
        <joint name="left_pinch" pos="-20 0 0" axis="1 0 0" type="slide" limited="true" range="0 15" actuatorfrclimited="false" actuatorgravcomp="true" />
        <geom name="left_pinch" pos="-23.2227 2.14457 1.54222" quat="0 0 0 1" type="mesh" friction="0" density="1" material="gripper_mat" mesh="iai_left_pinch" />
        <geom name="left_claw" pos="-7.33679 8.40771 9.739" quat="0 0 0 1" type="mesh" mass="1e-09" material="gripper_mat" mesh="iai_claw" />
      </body>
    </body>
  </worldbody>

  <contact>
    <pair geom1="right_side" geom2="right_pinch" name="pair_1" />
    <pair geom1="left_side" geom2="left_pinch" name="pair_2" />
    <exclude name="exclude_1" body1="gripper/base" body2="right_pinch" />
    <exclude name="exclude_2" body1="gripper/base" body2="left_pinch" />
  </contact>

  <equality>
    <joint name="new_equality" joint1="right_pinch" joint2="left_pinch" polycoef="0 1 0 0 0" />
  </equality>

  <actuator>
    <general name="gripper_actuator" joint="right_pinch" ctrllimited="true" ctrlrange="-10 10" actlimited="false" biastype="affine" gainprm="20000" biasprm="0 0 -10000" />
  </actuator>
</mujoco>