<?xml version='1.0' encoding='utf-8'?>
<mujoco model="iai_gripper">
  <!--robola compile-->
  <compiler angle="radian"/>

  <asset>
    <texture type="2d" colorspace="auto" name="gripper_tex" builtin="flat" rgb1="0.55 0.55 0.55" width="256" height="256" />
    <material name="gripper_mat" texture="gripper_tex" rgba="0.75 0.75 0.75 1" />
    <mesh name="iai_upper_body" content_type="model/stl" file="../../../assets/meshes/gripper/iai/upper_body.stl" scale="0.001 0.001 0.001" />
    <mesh name="iai_lower_body" content_type="model/stl" file="../../../assets/meshes/gripper/iai/lower_body.stl" scale="0.001 0.001 0.001" />
    <mesh name="iai_left_pinch" content_type="model/stl" file="../../../assets/meshes/gripper/iai/left_pinch.stl" scale="0.001 0.001 0.001" />
    <mesh name="iai_right_pinch" content_type="model/stl" file="../../../assets/meshes/gripper/iai/right_pinch.stl" scale="0.001 0.001 0.001" />
    <mesh name="iai_cable" content_type="model/stl" file="../../../assets/meshes/gripper/iai/cable.stl" scale="0.001 0.001 0.001" />
    <mesh name="iai_side" content_type="model/stl" file="../../../assets/meshes/gripper/iai/gripper_side.stl" scale="0.001 0.001 0.001" />
    <mesh name="iai_claw" content_type="model/stl" file="../../../assets/meshes/gripper/iai/claw.stl" scale="0.001 0.001 0.001" />
    <mesh name="iai_gripper_cover" content_type="model/stl" file="../../../assets/meshes/gripper/iai/gripper_cover.stl" scale="0.001 0.001 0.001" />
    <mesh name="iai_connect_part" content_type="model/stl" file="../../../assets/meshes/gripper/iai/connect_part.stl" scale="0.001 0.001 0.001" />
  </asset>

  <worldbody>
    <body name="gripper/base">
      <inertial pos="0 0 0.0002" mass="0.6" diaginertia="0.001 0.001 0.001" />
      <geom name="upper_body" pos="0.000545159 0 0.0021" quat="0 1 0 0" type="mesh" contype="0" conaffinity="0" density="5" material="gripper_mat" mesh="iai_upper_body" />
      <geom name="lower_body" pos="0 -0.0410198 -0.0147173" quat="0 1 0 0" type="mesh" group="2" material="gripper_mat" mesh="iai_lower_body" />
      <geom name="cable" pos="0.00559816 -0.0699537 -0.0479794" quat="0.707107 0 0.707107 0" type="mesh" group="2" material="gripper_mat" mesh="iai_cable" />
      <geom name="right_side" pos="0 -0.0802952 0" quat="1 0 0 0" type="mesh" material="gripper_mat" mesh="iai_side" />
      <geom name="left_side" pos="-0.0765432 -0.0806754 0" quat="1 0 0 0" type="mesh" material="gripper_mat" mesh="iai_side" />
      <geom name="cover" pos="0 0.18463 -0.0489517" quat="0 0 0 1" type="mesh" material="gripper_mat" mesh="iai_gripper_cover" />
      <geom name="connector" pos="0 0.000735604 -0.0340329" quat="0 0 0 1" type="mesh" material="gripper_mat" mesh="iai_connect_part" />
      <body name="right_pinch">
        <joint name="right_pinch" pos="0.02 0 0" axis="-1 0 0" type="slide" limited="true" range="-0.015 0.015" actuatorfrclimited="false" actuatorgravcomp="true" damping="0.2" armature="0.001" />
        <geom name="right_pinch" pos="0.0243746 0.00245222 0.00147149" quat="0 0 0 1" type="mesh" friction="0" density="1" material="gripper_mat" mesh="iai_right_pinch" />
        <geom name="right_claw" pos="0.00833277 0.0089508 -0.00681747" quat="0 1 0 0" type="mesh" mass="1e-09" material="gripper_mat" mesh="iai_claw" />
      </body>
      <body name="left_pinch">
        <joint name="left_pinch" pos="-0.02 0 0" axis="1 0 0" type="slide" limited="true" range="-0.015 0.015" actuatorfrclimited="false" actuatorgravcomp="true" damping="0.2" armature="0.001" />
        <geom name="left_pinch" pos="-0.0232227 0.00214457 0.00154222" quat="0 0 0 1" type="mesh" friction="0" density="1" material="gripper_mat" mesh="iai_left_pinch" />
        <geom name="left_claw" pos="-0.00733679 0.00840771 0.009739" quat="0 0 0 1" type="mesh" mass="1e-09" material="gripper_mat" mesh="iai_claw" />
      </body>
    </body>
  </worldbody>

  <contact>
    <pair geom1="right_side" geom2="right_pinch" name="gripper_pair_1" />
    <pair geom1="left_side" geom2="left_pinch" name="gripper_pair_2" />
    <exclude name="gripper_exclude_1" body1="gripper/base" body2="right_pinch" />
    <exclude name="gripper_exclude_2" body1="gripper/base" body2="left_pinch" />
  </contact>

  <equality>
    <joint name="new_equality" joint1="right_pinch" joint2="left_pinch" polycoef="0 1 0 0 0" />
  </equality>

  <actuator>
    <position name="gripper_actuator" joint="right_pinch" ctrllimited="true" ctrlrange="-0.015 0.015" kp="5" />
  </actuator>
</mujoco>